Creating test database for alias 'default' ('file:memorydb_default?mode=memory&cache=shared')...
Operations to perform:
  Synchronize unmigrated apps: messages, rest_framework, staticfiles
  Apply all migrations: accounts, admin, auth, authtoken, contenttypes, orders, sessions
Synchronizing apps without migrations:
  Creating tables...
    Running deferred SQL...
Running migrations:
  Applying contenttypes.0001_initial... OK
  Applying contenttypes.0002_remove_content_type_name... OK
  Applying auth.0001_initial... OK
  Applying auth.0002_alter_permission_name_max_length... OK
  Applying auth.0003_alter_user_email_max_length... OK
  Applying auth.0004_alter_user_username_opts... OK
  Applying auth.0005_alter_user_last_login_null... OK
  Applying auth.0006_require_contenttypes_0002... OK
  Applying auth.0007_alter_validators_add_error_messages... OK
  Applying auth.0008_alter_user_username_max_length... OK
  Applying auth.0009_alter_user_last_name_max_length... OK
  Applying auth.0010_alter_group_name_max_length... OK
  Applying auth.0011_update_proxy_permissions... OK
  Applying auth.0012_alter_user_first_name_max_length... OK
  Applying accounts.0001_initial... OK
  Applying accounts.0002_auto_20211125_2054... OK
  Applying orders.0001_initial... OK
  Applying accounts.0003_auto_20211130_1816... OK
  Applying accounts.0004_auto_20211130_1818... OK
  Applying accounts.0005_auto_20211130_1822... OK
  Applying admin.0001_initial... OK
  Applying admin.0002_logentry_remove_auto_add... OK
  Applying admin.0003_logentry_add_action_flag_choices... OK
  Applying authtoken.0001_initial... OK
  Applying authtoken.0002_auto_20160226_1747... OK
  Applying authtoken.0003_tokenproxy... OK
  Applying sessions.0001_initial... OK
System check identified no issues (0 silenced).
test_customer_fields (accounts.tests.tests_models.CustomerModelTest) ... ok
test_partner_table_fields (accounts.tests.tests_models.CustomerModelTest) ... ok
test_create_customer_fail_when_cpf_exists (accounts.tests.tests_views.CustomerViewTest) ... ok
test_create_customer_fail_when_missing_fields (accounts.tests.tests_views.CustomerViewTest) ... ok
test_create_new_customer (accounts.tests.tests_views.CustomerViewTest) ... ok
test_login_fail (accounts.tests.tests_views.LoginCustomerViewTest) ... ok
test_login_success (accounts.tests.tests_views.LoginCustomerViewTest) ... ok
test_login_fail (accounts.tests.tests_views.LoginPartnerViewTest) ... ok
test_login_success (accounts.tests.tests_views.LoginPartnerViewTest) ... ok
test_create_new_partner (accounts.tests.tests_views.PartnerViewTest) ... ok
test_create_partner_fail_when_missing_fields (accounts.tests.tests_views.PartnerViewTest) ... ok
test_create_user_fail_when_cpf_exists (accounts.tests.tests_views.PartnerViewTest) ... ok
test_a_customer_cannot_update_another_customer_data (accounts.tests.tests_views.SeachingAndUpdatingCustomerTest) ... ok
test_anonymous_cannot_search_for_a_specific_customer_by_id (accounts.tests.tests_views.SeachingAndUpdatingCustomerTest) ... ok
test_anyone_authenticated_can_search_for_a_specific_customer_by_id (accounts.tests.tests_views.SeachingAndUpdatingCustomerTest) ... ok
test_is_is_not_possible_to_search_for_a_customer_by_id_that_does_not_exist (accounts.tests.tests_views.SeachingAndUpdatingCustomerTest) ... ok
test_is_is_not_possible_to_update_a_customer_by_id_that_does_not_exist (accounts.tests.tests_views.SeachingAndUpdatingCustomerTest) ... ok
test_only_the_customer_himself_can_update_his_data (accounts.tests.tests_views.SeachingAndUpdatingCustomerTest) ... ok
test_a_partner_cannot_update_another_user_data (accounts.tests.tests_views.UpdatingPartnerTest) ... ok
test_is_is_not_possible_to_update_a_partner_by_id_that_does_not_exist (accounts.tests.tests_views.UpdatingPartnerTest) ... ok
test_only_the_partner_himself_can_update_his_data (accounts.tests.tests_views.UpdatingPartnerTest) ... ok
test_address_field_type (orders.tests.test_model.TestOrderModel) ... ok
test_address_field_value (orders.tests.test_model.TestOrderModel) ... ok
test_order_field_type (orders.tests.test_model.TestOrderModel) ... ok
test_order_field_value (orders.tests.test_model.TestOrderModel) ... ok
test_residence_field_type (orders.tests.test_model.TestOrderModel) ... ok
test_residence_field_value (orders.tests.test_model.TestOrderModel) ... ok
test_service_field_type (orders.tests.test_model.TestOrderModel) ... ok
test_service_field_value (orders.tests.test_model.TestOrderModel) ... ok
test_create_an_order_with_invalid_token (orders.tests.test_views.TestOrdersView)
Tentativa de criação com um token que ... ok
test_create_an_order_without_fields (orders.tests.test_views.TestOrdersView)
Teste mal sucedido de criação de ordem sem algum campo. ... ok
test_delete_order_by_customer (orders.tests.test_views.TestOrdersView)
Teste para deletar as ordens, só podem ser deletadas pelo customer ... ERROR
test_get_order_by_id_successful_with_customer_authentication (orders.tests.test_views.TestOrdersView)
Teste de request get bem sucedido de ordem logado com customer. ... ERROR
test_get_order_by_id_successful_with_partner_authentication (orders.tests.test_views.TestOrdersView)
Teste de request get bem sucedido de ordem logado com partner. ... ERROR
test_get_order_by_id_unsuccessful_without_authentication (orders.tests.test_views.TestOrdersView)
Teste de request get por id da order sem autenticação. ... ok
test_get_order_successful_with_customer_authentication (orders.tests.test_views.TestOrdersView)
Teste de request get bem sucedido de ordem logado com customer. ... ok
test_get_order_successful_with_partner_authentication (orders.tests.test_views.TestOrdersView)
Teste de request get bem sucedido de ordem logado com partner. ... ERROR
test_get_order_without_authentication (orders.tests.test_views.TestOrdersView)
Teste mal sucedido por não estar autenticado. ... ok
test_only_customer_can_create_an_successful_order (orders.tests.test_views.TestOrdersView)
Aqui a criação de ordem será bem sucedida, ... FAIL
test_order_accepted_by_partner_and_completed_by_customer (orders.tests.test_views.TestOrdersView)
teste de update para aceitar a ordem e completa-la ... ERROR
test_unsuccessful_order_accept_by_anonymous (orders.tests.test_views.TestOrdersView)
teste de update para aceitar a ordem com o usuário anônimo ... ERROR
test_unsuccessful_order_accept_by_customer (orders.tests.test_views.TestOrdersView)
teste de update para aceitar a ordem com usuário customer ... ERROR
test_unsuccessful_order_deleted_by_anonymous (orders.tests.test_views.TestOrdersView)
Teste mal sucedido de deletar uma ordem pelo anônimo ... ERROR
test_unsuccessful_order_deleted_by_partner (orders.tests.test_views.TestOrdersView)
Teste mal sucedido de deletar uma ordem pelo parceiro ... FAIL
test_unsuccessful_order_not_found (orders.tests.test_views.TestOrdersView)
Teste mal sucedido por não achar o id da ordem ... ok

======================================================================
ERROR: test_delete_order_by_customer (orders.tests.test_views.TestOrdersView)
Teste para deletar as ordens, só podem ser deletadas pelo customer
----------------------------------------------------------------------
Traceback (most recent call last):
  File "/home/mcromao/kenzie/q4/sprint3/capstone/cleango-django/venv/lib/python3.9/site-packages/django/db/models/fields/__init__.py", line 1823, in get_prep_value
    return int(value)
TypeError: int() argument must be a string, a bytes-like object or a number, not 'dict'

The above exception was the direct cause of the following exception:

Traceback (most recent call last):
  File "/home/mcromao/kenzie/q4/sprint3/capstone/cleango-django/orders/tests/test_views.py", line 510, in test_delete_order_by_customer
    token, _ = Token.objects.get_or_create(user=self.customer_login_data)
  File "/home/mcromao/kenzie/q4/sprint3/capstone/cleango-django/venv/lib/python3.9/site-packages/django/db/models/manager.py", line 85, in manager_method
    return getattr(self.get_queryset(), name)(*args, **kwargs)
  File "/home/mcromao/kenzie/q4/sprint3/capstone/cleango-django/venv/lib/python3.9/site-packages/django/db/models/query.py", line 581, in get_or_create
    return self.get(**kwargs), False
  File "/home/mcromao/kenzie/q4/sprint3/capstone/cleango-django/venv/lib/python3.9/site-packages/django/db/models/query.py", line 424, in get
    clone = self._chain() if self.query.combinator else self.filter(*args, **kwargs)
  File "/home/mcromao/kenzie/q4/sprint3/capstone/cleango-django/venv/lib/python3.9/site-packages/django/db/models/query.py", line 941, in filter
    return self._filter_or_exclude(False, args, kwargs)
  File "/home/mcromao/kenzie/q4/sprint3/capstone/cleango-django/venv/lib/python3.9/site-packages/django/db/models/query.py", line 961, in _filter_or_exclude
    clone._filter_or_exclude_inplace(negate, args, kwargs)
  File "/home/mcromao/kenzie/q4/sprint3/capstone/cleango-django/venv/lib/python3.9/site-packages/django/db/models/query.py", line 968, in _filter_or_exclude_inplace
    self._query.add_q(Q(*args, **kwargs))
  File "/home/mcromao/kenzie/q4/sprint3/capstone/cleango-django/venv/lib/python3.9/site-packages/django/db/models/sql/query.py", line 1393, in add_q
    clause, _ = self._add_q(q_object, self.used_aliases)
  File "/home/mcromao/kenzie/q4/sprint3/capstone/cleango-django/venv/lib/python3.9/site-packages/django/db/models/sql/query.py", line 1412, in _add_q
    child_clause, needed_inner = self.build_filter(
  File "/home/mcromao/kenzie/q4/sprint3/capstone/cleango-django/venv/lib/python3.9/site-packages/django/db/models/sql/query.py", line 1347, in build_filter
    condition = self.build_lookup(lookups, col, value)
  File "/home/mcromao/kenzie/q4/sprint3/capstone/cleango-django/venv/lib/python3.9/site-packages/django/db/models/sql/query.py", line 1193, in build_lookup
    lookup = lookup_class(lhs, rhs)
  File "/home/mcromao/kenzie/q4/sprint3/capstone/cleango-django/venv/lib/python3.9/site-packages/django/db/models/lookups.py", line 25, in __init__
    self.rhs = self.get_prep_lookup()
  File "/home/mcromao/kenzie/q4/sprint3/capstone/cleango-django/venv/lib/python3.9/site-packages/django/db/models/fields/related_lookups.py", line 117, in get_prep_lookup
    self.rhs = target_field.get_prep_value(self.rhs)
  File "/home/mcromao/kenzie/q4/sprint3/capstone/cleango-django/venv/lib/python3.9/site-packages/django/db/models/fields/__init__.py", line 1825, in get_prep_value
    raise e.__class__(
TypeError: Field 'id' expected a number but got {'username': 'epchinbot@teste.com', 'password': 'pbkdf2_sha256$260000$tJ4lKKh2TyxwNiITAcYKNI$dtj+V3SpM7GizimO8qpvMZ4Aw+/DzrLQ70W3WOVWt2s='}.

======================================================================
ERROR: test_get_order_by_id_successful_with_customer_authentication (orders.tests.test_views.TestOrdersView)
Teste de request get bem sucedido de ordem logado com customer.
----------------------------------------------------------------------
Traceback (most recent call last):
  File "/home/mcromao/kenzie/q4/sprint3/capstone/cleango-django/venv/lib/python3.9/site-packages/django/db/models/fields/__init__.py", line 1823, in get_prep_value
    return int(value)
TypeError: int() argument must be a string, a bytes-like object or a number, not 'dict'

The above exception was the direct cause of the following exception:

Traceback (most recent call last):
  File "/home/mcromao/kenzie/q4/sprint3/capstone/cleango-django/orders/tests/test_views.py", line 347, in test_get_order_by_id_successful_with_customer_authentication
    token, _ = Token.objects.get_or_create(user=self.customer_login_data)
  File "/home/mcromao/kenzie/q4/sprint3/capstone/cleango-django/venv/lib/python3.9/site-packages/django/db/models/manager.py", line 85, in manager_method
    return getattr(self.get_queryset(), name)(*args, **kwargs)
  File "/home/mcromao/kenzie/q4/sprint3/capstone/cleango-django/venv/lib/python3.9/site-packages/django/db/models/query.py", line 581, in get_or_create
    return self.get(**kwargs), False
  File "/home/mcromao/kenzie/q4/sprint3/capstone/cleango-django/venv/lib/python3.9/site-packages/django/db/models/query.py", line 424, in get
    clone = self._chain() if self.query.combinator else self.filter(*args, **kwargs)
  File "/home/mcromao/kenzie/q4/sprint3/capstone/cleango-django/venv/lib/python3.9/site-packages/django/db/models/query.py", line 941, in filter
    return self._filter_or_exclude(False, args, kwargs)
  File "/home/mcromao/kenzie/q4/sprint3/capstone/cleango-django/venv/lib/python3.9/site-packages/django/db/models/query.py", line 961, in _filter_or_exclude
    clone._filter_or_exclude_inplace(negate, args, kwargs)
  File "/home/mcromao/kenzie/q4/sprint3/capstone/cleango-django/venv/lib/python3.9/site-packages/django/db/models/query.py", line 968, in _filter_or_exclude_inplace
    self._query.add_q(Q(*args, **kwargs))
  File "/home/mcromao/kenzie/q4/sprint3/capstone/cleango-django/venv/lib/python3.9/site-packages/django/db/models/sql/query.py", line 1393, in add_q
    clause, _ = self._add_q(q_object, self.used_aliases)
  File "/home/mcromao/kenzie/q4/sprint3/capstone/cleango-django/venv/lib/python3.9/site-packages/django/db/models/sql/query.py", line 1412, in _add_q
    child_clause, needed_inner = self.build_filter(
  File "/home/mcromao/kenzie/q4/sprint3/capstone/cleango-django/venv/lib/python3.9/site-packages/django/db/models/sql/query.py", line 1347, in build_filter
    condition = self.build_lookup(lookups, col, value)
  File "/home/mcromao/kenzie/q4/sprint3/capstone/cleango-django/venv/lib/python3.9/site-packages/django/db/models/sql/query.py", line 1193, in build_lookup
    lookup = lookup_class(lhs, rhs)
  File "/home/mcromao/kenzie/q4/sprint3/capstone/cleango-django/venv/lib/python3.9/site-packages/django/db/models/lookups.py", line 25, in __init__
    self.rhs = self.get_prep_lookup()
  File "/home/mcromao/kenzie/q4/sprint3/capstone/cleango-django/venv/lib/python3.9/site-packages/django/db/models/fields/related_lookups.py", line 117, in get_prep_lookup
    self.rhs = target_field.get_prep_value(self.rhs)
  File "/home/mcromao/kenzie/q4/sprint3/capstone/cleango-django/venv/lib/python3.9/site-packages/django/db/models/fields/__init__.py", line 1825, in get_prep_value
    raise e.__class__(
TypeError: Field 'id' expected a number but got {'username': 'epchinbot@teste.com', 'password': 'pbkdf2_sha256$260000$tJ4lKKh2TyxwNiITAcYKNI$dtj+V3SpM7GizimO8qpvMZ4Aw+/DzrLQ70W3WOVWt2s='}.

======================================================================
ERROR: test_get_order_by_id_successful_with_partner_authentication (orders.tests.test_views.TestOrdersView)
Teste de request get bem sucedido de ordem logado com partner.
----------------------------------------------------------------------
Traceback (most recent call last):
  File "/home/mcromao/kenzie/q4/sprint3/capstone/cleango-django/venv/lib/python3.9/site-packages/django/db/models/fields/__init__.py", line 1823, in get_prep_value
    return int(value)
TypeError: int() argument must be a string, a bytes-like object or a number, not 'dict'

The above exception was the direct cause of the following exception:

Traceback (most recent call last):
  File "/home/mcromao/kenzie/q4/sprint3/capstone/cleango-django/orders/tests/test_views.py", line 378, in test_get_order_by_id_successful_with_partner_authentication
    token, _ = Token.objects.get_or_create(user=self.partner_login_data)
  File "/home/mcromao/kenzie/q4/sprint3/capstone/cleango-django/venv/lib/python3.9/site-packages/django/db/models/manager.py", line 85, in manager_method
    return getattr(self.get_queryset(), name)(*args, **kwargs)
  File "/home/mcromao/kenzie/q4/sprint3/capstone/cleango-django/venv/lib/python3.9/site-packages/django/db/models/query.py", line 581, in get_or_create
    return self.get(**kwargs), False
  File "/home/mcromao/kenzie/q4/sprint3/capstone/cleango-django/venv/lib/python3.9/site-packages/django/db/models/query.py", line 424, in get
    clone = self._chain() if self.query.combinator else self.filter(*args, **kwargs)
  File "/home/mcromao/kenzie/q4/sprint3/capstone/cleango-django/venv/lib/python3.9/site-packages/django/db/models/query.py", line 941, in filter
    return self._filter_or_exclude(False, args, kwargs)
  File "/home/mcromao/kenzie/q4/sprint3/capstone/cleango-django/venv/lib/python3.9/site-packages/django/db/models/query.py", line 961, in _filter_or_exclude
    clone._filter_or_exclude_inplace(negate, args, kwargs)
  File "/home/mcromao/kenzie/q4/sprint3/capstone/cleango-django/venv/lib/python3.9/site-packages/django/db/models/query.py", line 968, in _filter_or_exclude_inplace
    self._query.add_q(Q(*args, **kwargs))
  File "/home/mcromao/kenzie/q4/sprint3/capstone/cleango-django/venv/lib/python3.9/site-packages/django/db/models/sql/query.py", line 1393, in add_q
    clause, _ = self._add_q(q_object, self.used_aliases)
  File "/home/mcromao/kenzie/q4/sprint3/capstone/cleango-django/venv/lib/python3.9/site-packages/django/db/models/sql/query.py", line 1412, in _add_q
    child_clause, needed_inner = self.build_filter(
  File "/home/mcromao/kenzie/q4/sprint3/capstone/cleango-django/venv/lib/python3.9/site-packages/django/db/models/sql/query.py", line 1347, in build_filter
    condition = self.build_lookup(lookups, col, value)
  File "/home/mcromao/kenzie/q4/sprint3/capstone/cleango-django/venv/lib/python3.9/site-packages/django/db/models/sql/query.py", line 1193, in build_lookup
    lookup = lookup_class(lhs, rhs)
  File "/home/mcromao/kenzie/q4/sprint3/capstone/cleango-django/venv/lib/python3.9/site-packages/django/db/models/lookups.py", line 25, in __init__
    self.rhs = self.get_prep_lookup()
  File "/home/mcromao/kenzie/q4/sprint3/capstone/cleango-django/venv/lib/python3.9/site-packages/django/db/models/fields/related_lookups.py", line 117, in get_prep_lookup
    self.rhs = target_field.get_prep_value(self.rhs)
  File "/home/mcromao/kenzie/q4/sprint3/capstone/cleango-django/venv/lib/python3.9/site-packages/django/db/models/fields/__init__.py", line 1825, in get_prep_value
    raise e.__class__(
TypeError: Field 'id' expected a number but got {'username': 'partner@email.com', 'password': 'pbkdf2_sha256$260000$WAcIUrtjBKGTHo4uVVp1ri$O5D5Cf/SWG2mlzIFYx9eYAGNy65pL3AbVqnbNwTbwQg='}.

======================================================================
ERROR: test_get_order_successful_with_partner_authentication (orders.tests.test_views.TestOrdersView)
Teste de request get bem sucedido de ordem logado com partner.
----------------------------------------------------------------------
Traceback (most recent call last):
  File "/home/mcromao/kenzie/q4/sprint3/capstone/cleango-django/venv/lib/python3.9/site-packages/django/db/models/fields/__init__.py", line 1823, in get_prep_value
    return int(value)
TypeError: int() argument must be a string, a bytes-like object or a number, not 'dict'

The above exception was the direct cause of the following exception:

Traceback (most recent call last):
  File "/home/mcromao/kenzie/q4/sprint3/capstone/cleango-django/orders/tests/test_views.py", line 295, in test_get_order_successful_with_partner_authentication
    token, _ = Token.objects.get_or_create(user=self.partner_login_data)
  File "/home/mcromao/kenzie/q4/sprint3/capstone/cleango-django/venv/lib/python3.9/site-packages/django/db/models/manager.py", line 85, in manager_method
    return getattr(self.get_queryset(), name)(*args, **kwargs)
  File "/home/mcromao/kenzie/q4/sprint3/capstone/cleango-django/venv/lib/python3.9/site-packages/django/db/models/query.py", line 581, in get_or_create
    return self.get(**kwargs), False
  File "/home/mcromao/kenzie/q4/sprint3/capstone/cleango-django/venv/lib/python3.9/site-packages/django/db/models/query.py", line 424, in get
    clone = self._chain() if self.query.combinator else self.filter(*args, **kwargs)
  File "/home/mcromao/kenzie/q4/sprint3/capstone/cleango-django/venv/lib/python3.9/site-packages/django/db/models/query.py", line 941, in filter
    return self._filter_or_exclude(False, args, kwargs)
  File "/home/mcromao/kenzie/q4/sprint3/capstone/cleango-django/venv/lib/python3.9/site-packages/django/db/models/query.py", line 961, in _filter_or_exclude
    clone._filter_or_exclude_inplace(negate, args, kwargs)
  File "/home/mcromao/kenzie/q4/sprint3/capstone/cleango-django/venv/lib/python3.9/site-packages/django/db/models/query.py", line 968, in _filter_or_exclude_inplace
    self._query.add_q(Q(*args, **kwargs))
  File "/home/mcromao/kenzie/q4/sprint3/capstone/cleango-django/venv/lib/python3.9/site-packages/django/db/models/sql/query.py", line 1393, in add_q
    clause, _ = self._add_q(q_object, self.used_aliases)
  File "/home/mcromao/kenzie/q4/sprint3/capstone/cleango-django/venv/lib/python3.9/site-packages/django/db/models/sql/query.py", line 1412, in _add_q
    child_clause, needed_inner = self.build_filter(
  File "/home/mcromao/kenzie/q4/sprint3/capstone/cleango-django/venv/lib/python3.9/site-packages/django/db/models/sql/query.py", line 1347, in build_filter
    condition = self.build_lookup(lookups, col, value)
  File "/home/mcromao/kenzie/q4/sprint3/capstone/cleango-django/venv/lib/python3.9/site-packages/django/db/models/sql/query.py", line 1193, in build_lookup
    lookup = lookup_class(lhs, rhs)
  File "/home/mcromao/kenzie/q4/sprint3/capstone/cleango-django/venv/lib/python3.9/site-packages/django/db/models/lookups.py", line 25, in __init__
    self.rhs = self.get_prep_lookup()
  File "/home/mcromao/kenzie/q4/sprint3/capstone/cleango-django/venv/lib/python3.9/site-packages/django/db/models/fields/related_lookups.py", line 117, in get_prep_lookup
    self.rhs = target_field.get_prep_value(self.rhs)
  File "/home/mcromao/kenzie/q4/sprint3/capstone/cleango-django/venv/lib/python3.9/site-packages/django/db/models/fields/__init__.py", line 1825, in get_prep_value
    raise e.__class__(
TypeError: Field 'id' expected a number but got {'username': 'partner@email.com', 'password': 'pbkdf2_sha256$260000$WAcIUrtjBKGTHo4uVVp1ri$O5D5Cf/SWG2mlzIFYx9eYAGNy65pL3AbVqnbNwTbwQg='}.

======================================================================
ERROR: test_order_accepted_by_partner_and_completed_by_customer (orders.tests.test_views.TestOrdersView)
teste de update para aceitar a ordem e completa-la
----------------------------------------------------------------------
Traceback (most recent call last):
  File "/home/mcromao/kenzie/q4/sprint3/capstone/cleango-django/venv/lib/python3.9/site-packages/django/db/models/fields/__init__.py", line 1823, in get_prep_value
    return int(value)
TypeError: int() argument must be a string, a bytes-like object or a number, not 'dict'

The above exception was the direct cause of the following exception:

Traceback (most recent call last):
  File "/home/mcromao/kenzie/q4/sprint3/capstone/cleango-django/orders/tests/test_views.py", line 409, in test_order_accepted_by_partner_and_completed_by_customer
    token, _ = Token.objects.get_or_create(user=self.customer_login_data)
  File "/home/mcromao/kenzie/q4/sprint3/capstone/cleango-django/venv/lib/python3.9/site-packages/django/db/models/manager.py", line 85, in manager_method
    return getattr(self.get_queryset(), name)(*args, **kwargs)
  File "/home/mcromao/kenzie/q4/sprint3/capstone/cleango-django/venv/lib/python3.9/site-packages/django/db/models/query.py", line 581, in get_or_create
    return self.get(**kwargs), False
  File "/home/mcromao/kenzie/q4/sprint3/capstone/cleango-django/venv/lib/python3.9/site-packages/django/db/models/query.py", line 424, in get
    clone = self._chain() if self.query.combinator else self.filter(*args, **kwargs)
  File "/home/mcromao/kenzie/q4/sprint3/capstone/cleango-django/venv/lib/python3.9/site-packages/django/db/models/query.py", line 941, in filter
    return self._filter_or_exclude(False, args, kwargs)
  File "/home/mcromao/kenzie/q4/sprint3/capstone/cleango-django/venv/lib/python3.9/site-packages/django/db/models/query.py", line 961, in _filter_or_exclude
    clone._filter_or_exclude_inplace(negate, args, kwargs)
  File "/home/mcromao/kenzie/q4/sprint3/capstone/cleango-django/venv/lib/python3.9/site-packages/django/db/models/query.py", line 968, in _filter_or_exclude_inplace
    self._query.add_q(Q(*args, **kwargs))
  File "/home/mcromao/kenzie/q4/sprint3/capstone/cleango-django/venv/lib/python3.9/site-packages/django/db/models/sql/query.py", line 1393, in add_q
    clause, _ = self._add_q(q_object, self.used_aliases)
  File "/home/mcromao/kenzie/q4/sprint3/capstone/cleango-django/venv/lib/python3.9/site-packages/django/db/models/sql/query.py", line 1412, in _add_q
    child_clause, needed_inner = self.build_filter(
  File "/home/mcromao/kenzie/q4/sprint3/capstone/cleango-django/venv/lib/python3.9/site-packages/django/db/models/sql/query.py", line 1347, in build_filter
    condition = self.build_lookup(lookups, col, value)
  File "/home/mcromao/kenzie/q4/sprint3/capstone/cleango-django/venv/lib/python3.9/site-packages/django/db/models/sql/query.py", line 1193, in build_lookup
    lookup = lookup_class(lhs, rhs)
  File "/home/mcromao/kenzie/q4/sprint3/capstone/cleango-django/venv/lib/python3.9/site-packages/django/db/models/lookups.py", line 25, in __init__
    self.rhs = self.get_prep_lookup()
  File "/home/mcromao/kenzie/q4/sprint3/capstone/cleango-django/venv/lib/python3.9/site-packages/django/db/models/fields/related_lookups.py", line 117, in get_prep_lookup
    self.rhs = target_field.get_prep_value(self.rhs)
  File "/home/mcromao/kenzie/q4/sprint3/capstone/cleango-django/venv/lib/python3.9/site-packages/django/db/models/fields/__init__.py", line 1825, in get_prep_value
    raise e.__class__(
TypeError: Field 'id' expected a number but got {'username': 'epchinbot@teste.com', 'password': 'pbkdf2_sha256$260000$tJ4lKKh2TyxwNiITAcYKNI$dtj+V3SpM7GizimO8qpvMZ4Aw+/DzrLQ70W3WOVWt2s='}.

======================================================================
ERROR: test_unsuccessful_order_accept_by_anonymous (orders.tests.test_views.TestOrdersView)
teste de update para aceitar a ordem com o usuário anônimo
----------------------------------------------------------------------
Traceback (most recent call last):
  File "/home/mcromao/kenzie/q4/sprint3/capstone/cleango-django/venv/lib/python3.9/site-packages/django/db/models/fields/__init__.py", line 1823, in get_prep_value
    return int(value)
TypeError: int() argument must be a string, a bytes-like object or a number, not 'dict'

The above exception was the direct cause of the following exception:

Traceback (most recent call last):
  File "/home/mcromao/kenzie/q4/sprint3/capstone/cleango-django/orders/tests/test_views.py", line 481, in test_unsuccessful_order_accept_by_anonymous
    token, _ = Token.objects.get_or_create(user=self.customer_login_data)
  File "/home/mcromao/kenzie/q4/sprint3/capstone/cleango-django/venv/lib/python3.9/site-packages/django/db/models/manager.py", line 85, in manager_method
    return getattr(self.get_queryset(), name)(*args, **kwargs)
  File "/home/mcromao/kenzie/q4/sprint3/capstone/cleango-django/venv/lib/python3.9/site-packages/django/db/models/query.py", line 581, in get_or_create
    return self.get(**kwargs), False
  File "/home/mcromao/kenzie/q4/sprint3/capstone/cleango-django/venv/lib/python3.9/site-packages/django/db/models/query.py", line 424, in get
    clone = self._chain() if self.query.combinator else self.filter(*args, **kwargs)
  File "/home/mcromao/kenzie/q4/sprint3/capstone/cleango-django/venv/lib/python3.9/site-packages/django/db/models/query.py", line 941, in filter
    return self._filter_or_exclude(False, args, kwargs)
  File "/home/mcromao/kenzie/q4/sprint3/capstone/cleango-django/venv/lib/python3.9/site-packages/django/db/models/query.py", line 961, in _filter_or_exclude
    clone._filter_or_exclude_inplace(negate, args, kwargs)
  File "/home/mcromao/kenzie/q4/sprint3/capstone/cleango-django/venv/lib/python3.9/site-packages/django/db/models/query.py", line 968, in _filter_or_exclude_inplace
    self._query.add_q(Q(*args, **kwargs))
  File "/home/mcromao/kenzie/q4/sprint3/capstone/cleango-django/venv/lib/python3.9/site-packages/django/db/models/sql/query.py", line 1393, in add_q
    clause, _ = self._add_q(q_object, self.used_aliases)
  File "/home/mcromao/kenzie/q4/sprint3/capstone/cleango-django/venv/lib/python3.9/site-packages/django/db/models/sql/query.py", line 1412, in _add_q
    child_clause, needed_inner = self.build_filter(
  File "/home/mcromao/kenzie/q4/sprint3/capstone/cleango-django/venv/lib/python3.9/site-packages/django/db/models/sql/query.py", line 1347, in build_filter
    condition = self.build_lookup(lookups, col, value)
  File "/home/mcromao/kenzie/q4/sprint3/capstone/cleango-django/venv/lib/python3.9/site-packages/django/db/models/sql/query.py", line 1193, in build_lookup
    lookup = lookup_class(lhs, rhs)
  File "/home/mcromao/kenzie/q4/sprint3/capstone/cleango-django/venv/lib/python3.9/site-packages/django/db/models/lookups.py", line 25, in __init__
    self.rhs = self.get_prep_lookup()
  File "/home/mcromao/kenzie/q4/sprint3/capstone/cleango-django/venv/lib/python3.9/site-packages/django/db/models/fields/related_lookups.py", line 117, in get_prep_lookup
    self.rhs = target_field.get_prep_value(self.rhs)
  File "/home/mcromao/kenzie/q4/sprint3/capstone/cleango-django/venv/lib/python3.9/site-packages/django/db/models/fields/__init__.py", line 1825, in get_prep_value
    raise e.__class__(
TypeError: Field 'id' expected a number but got {'username': 'epchinbot@teste.com', 'password': 'pbkdf2_sha256$260000$tJ4lKKh2TyxwNiITAcYKNI$dtj+V3SpM7GizimO8qpvMZ4Aw+/DzrLQ70W3WOVWt2s='}.

======================================================================
ERROR: test_unsuccessful_order_accept_by_customer (orders.tests.test_views.TestOrdersView)
teste de update para aceitar a ordem com usuário customer
----------------------------------------------------------------------
Traceback (most recent call last):
  File "/home/mcromao/kenzie/q4/sprint3/capstone/cleango-django/orders/tests/test_views.py", line 455, in test_unsuccessful_order_accept_by_customer
    token, _ = Token.objects.get_or_create(user=self.customer)
  File "/home/mcromao/kenzie/q4/sprint3/capstone/cleango-django/venv/lib/python3.9/site-packages/django/db/models/manager.py", line 85, in manager_method
    return getattr(self.get_queryset(), name)(*args, **kwargs)
  File "/home/mcromao/kenzie/q4/sprint3/capstone/cleango-django/venv/lib/python3.9/site-packages/django/db/models/query.py", line 581, in get_or_create
    return self.get(**kwargs), False
  File "/home/mcromao/kenzie/q4/sprint3/capstone/cleango-django/venv/lib/python3.9/site-packages/django/db/models/query.py", line 424, in get
    clone = self._chain() if self.query.combinator else self.filter(*args, **kwargs)
  File "/home/mcromao/kenzie/q4/sprint3/capstone/cleango-django/venv/lib/python3.9/site-packages/django/db/models/query.py", line 941, in filter
    return self._filter_or_exclude(False, args, kwargs)
  File "/home/mcromao/kenzie/q4/sprint3/capstone/cleango-django/venv/lib/python3.9/site-packages/django/db/models/query.py", line 961, in _filter_or_exclude
    clone._filter_or_exclude_inplace(negate, args, kwargs)
  File "/home/mcromao/kenzie/q4/sprint3/capstone/cleango-django/venv/lib/python3.9/site-packages/django/db/models/query.py", line 968, in _filter_or_exclude_inplace
    self._query.add_q(Q(*args, **kwargs))
  File "/home/mcromao/kenzie/q4/sprint3/capstone/cleango-django/venv/lib/python3.9/site-packages/django/db/models/sql/query.py", line 1393, in add_q
    clause, _ = self._add_q(q_object, self.used_aliases)
  File "/home/mcromao/kenzie/q4/sprint3/capstone/cleango-django/venv/lib/python3.9/site-packages/django/db/models/sql/query.py", line 1412, in _add_q
    child_clause, needed_inner = self.build_filter(
  File "/home/mcromao/kenzie/q4/sprint3/capstone/cleango-django/venv/lib/python3.9/site-packages/django/db/models/sql/query.py", line 1320, in build_filter
    self.check_related_objects(join_info.final_field, value, join_info.opts)
  File "/home/mcromao/kenzie/q4/sprint3/capstone/cleango-django/venv/lib/python3.9/site-packages/django/db/models/sql/query.py", line 1147, in check_related_objects
    self.check_query_object_type(value, opts, field)
  File "/home/mcromao/kenzie/q4/sprint3/capstone/cleango-django/venv/lib/python3.9/site-packages/django/db/models/sql/query.py", line 1128, in check_query_object_type
    raise ValueError(
ValueError: Cannot query "Customer object (1)": Must be "User" instance.

======================================================================
ERROR: test_unsuccessful_order_deleted_by_anonymous (orders.tests.test_views.TestOrdersView)
Teste mal sucedido de deletar uma ordem pelo anônimo
----------------------------------------------------------------------
Traceback (most recent call last):
  File "/home/mcromao/kenzie/q4/sprint3/capstone/cleango-django/venv/lib/python3.9/site-packages/django/db/models/fields/__init__.py", line 1823, in get_prep_value
    return int(value)
TypeError: int() argument must be a string, a bytes-like object or a number, not 'dict'

The above exception was the direct cause of the following exception:

Traceback (most recent call last):
  File "/home/mcromao/kenzie/q4/sprint3/capstone/cleango-django/orders/tests/test_views.py", line 554, in test_unsuccessful_order_deleted_by_anonymous
    token, _ = Token.objects.get_or_create(user=self.customer_login_data)
  File "/home/mcromao/kenzie/q4/sprint3/capstone/cleango-django/venv/lib/python3.9/site-packages/django/db/models/manager.py", line 85, in manager_method
    return getattr(self.get_queryset(), name)(*args, **kwargs)
  File "/home/mcromao/kenzie/q4/sprint3/capstone/cleango-django/venv/lib/python3.9/site-packages/django/db/models/query.py", line 581, in get_or_create
    return self.get(**kwargs), False
  File "/home/mcromao/kenzie/q4/sprint3/capstone/cleango-django/venv/lib/python3.9/site-packages/django/db/models/query.py", line 424, in get
    clone = self._chain() if self.query.combinator else self.filter(*args, **kwargs)
  File "/home/mcromao/kenzie/q4/sprint3/capstone/cleango-django/venv/lib/python3.9/site-packages/django/db/models/query.py", line 941, in filter
    return self._filter_or_exclude(False, args, kwargs)
  File "/home/mcromao/kenzie/q4/sprint3/capstone/cleango-django/venv/lib/python3.9/site-packages/django/db/models/query.py", line 961, in _filter_or_exclude
    clone._filter_or_exclude_inplace(negate, args, kwargs)
  File "/home/mcromao/kenzie/q4/sprint3/capstone/cleango-django/venv/lib/python3.9/site-packages/django/db/models/query.py", line 968, in _filter_or_exclude_inplace
    self._query.add_q(Q(*args, **kwargs))
  File "/home/mcromao/kenzie/q4/sprint3/capstone/cleango-django/venv/lib/python3.9/site-packages/django/db/models/sql/query.py", line 1393, in add_q
    clause, _ = self._add_q(q_object, self.used_aliases)
  File "/home/mcromao/kenzie/q4/sprint3/capstone/cleango-django/venv/lib/python3.9/site-packages/django/db/models/sql/query.py", line 1412, in _add_q
    child_clause, needed_inner = self.build_filter(
  File "/home/mcromao/kenzie/q4/sprint3/capstone/cleango-django/venv/lib/python3.9/site-packages/django/db/models/sql/query.py", line 1347, in build_filter
    condition = self.build_lookup(lookups, col, value)
  File "/home/mcromao/kenzie/q4/sprint3/capstone/cleango-django/venv/lib/python3.9/site-packages/django/db/models/sql/query.py", line 1193, in build_lookup
    lookup = lookup_class(lhs, rhs)
  File "/home/mcromao/kenzie/q4/sprint3/capstone/cleango-django/venv/lib/python3.9/site-packages/django/db/models/lookups.py", line 25, in __init__
    self.rhs = self.get_prep_lookup()
  File "/home/mcromao/kenzie/q4/sprint3/capstone/cleango-django/venv/lib/python3.9/site-packages/django/db/models/fields/related_lookups.py", line 117, in get_prep_lookup
    self.rhs = target_field.get_prep_value(self.rhs)
  File "/home/mcromao/kenzie/q4/sprint3/capstone/cleango-django/venv/lib/python3.9/site-packages/django/db/models/fields/__init__.py", line 1825, in get_prep_value
    raise e.__class__(
TypeError: Field 'id' expected a number but got {'username': 'epchinbot@teste.com', 'password': 'pbkdf2_sha256$260000$tJ4lKKh2TyxwNiITAcYKNI$dtj+V3SpM7GizimO8qpvMZ4Aw+/DzrLQ70W3WOVWt2s='}.

======================================================================
FAIL: test_only_customer_can_create_an_successful_order (orders.tests.test_views.TestOrdersView)
Aqui a criação de ordem será bem sucedida,
----------------------------------------------------------------------
Traceback (most recent call last):
  File "/home/mcromao/kenzie/q4/sprint3/capstone/cleango-django/orders/tests/test_views.py", line 181, in test_only_customer_can_create_an_successful_order
    self.assertDictEqual(
AssertionError: {'id'[82 chars].0, 'completed': False, 'opened': True, 'custo[406 chars]al'}} != {'id'[82 chars].0, 'residence': 'Casa', 'service': 'Limpeza R[214 chars]00'}}
Diff is 869 characters long. Set self.maxDiff to None to see it.

======================================================================
FAIL: test_unsuccessful_order_deleted_by_partner (orders.tests.test_views.TestOrdersView)
Teste mal sucedido de deletar uma ordem pelo parceiro
----------------------------------------------------------------------
Traceback (most recent call last):
  File "/home/mcromao/kenzie/q4/sprint3/capstone/cleango-django/orders/tests/test_views.py", line 546, in test_unsuccessful_order_deleted_by_partner
    self.assertEqual(403, response.status_code)
AssertionError: 403 != 404

----------------------------------------------------------------------
Ran 45 tests in 3.726s

FAILED (failures=2, errors=8)
Destroying test database for alias 'default' ('file:memorydb_default?mode=memory&cache=shared')...
Token Partner 026c96e0eb4865d04ed2cad84f64cec245a982c7
